2018-05-09 19:46:22,102 ERROR: Exception on /explore [GET] [in c:\users\castle\documents\microblog\venv\lib\site-packages\flask\app.py:1560]
Traceback (most recent call last):
  File "c:\users\castle\documents\microblog\venv\lib\site-packages\flask\app.py", line 1982, in wsgi_app
    response = self.full_dispatch_request()
  File "c:\users\castle\documents\microblog\venv\lib\site-packages\flask\app.py", line 1614, in full_dispatch_request
    rv = self.handle_user_exception(e)
  File "c:\users\castle\documents\microblog\venv\lib\site-packages\flask\app.py", line 1517, in handle_user_exception
    reraise(exc_type, exc_value, tb)
  File "c:\users\castle\documents\microblog\venv\lib\site-packages\flask\_compat.py", line 33, in reraise
    raise value
  File "c:\users\castle\documents\microblog\venv\lib\site-packages\flask\app.py", line 1612, in full_dispatch_request
    rv = self.dispatch_request()
  File "c:\users\castle\documents\microblog\venv\lib\site-packages\flask\app.py", line 1598, in dispatch_request
    return self.view_functions[rule.endpoint](**req.view_args)
  File "c:\users\castle\documents\microblog\venv\lib\site-packages\flask_login\utils.py", line 261, in decorated_view
    return func(*args, **kwargs)
  File "C:\Users\Castle\Documents\microblog\app\routes.py", line 157, in explore
    next_url=next_url, prev_url=prev_url)
  File "c:\users\castle\documents\microblog\venv\lib\site-packages\flask\templating.py", line 134, in render_template
    context, ctx.app)
  File "c:\users\castle\documents\microblog\venv\lib\site-packages\flask\templating.py", line 116, in _render
    rv = template.render(context)
  File "c:\users\castle\documents\microblog\venv\lib\site-packages\jinja2\asyncsupport.py", line 76, in render
    return original_render(self, *args, **kwargs)
  File "c:\users\castle\documents\microblog\venv\lib\site-packages\jinja2\environment.py", line 1008, in render
    return self.environment.handle_exception(exc_info, True)
  File "c:\users\castle\documents\microblog\venv\lib\site-packages\jinja2\environment.py", line 780, in handle_exception
    reraise(exc_type, exc_value, tb)
  File "c:\users\castle\documents\microblog\venv\lib\site-packages\jinja2\_compat.py", line 37, in reraise
    raise value.with_traceback(tb)
  File "C:\Users\Castle\Documents\microblog\app\templates\index.html", line 1, in top-level template code
    {% extends "base.html" %}
  File "C:\Users\Castle\Documents\microblog\app\templates\base.html", line 32, in top-level template code
    {% block content %}{% endblock %}
  File "C:\Users\Castle\Documents\microblog\app\templates\index.html", line 19, in block "content"
    {% include '_post.html' %}
  File "C:\Users\Castle\Documents\microblog\app\templates\_post.html", line 10, in top-level template code
    <br><a href="{{url_for('emailpost')}}{{post.id}}">Send to Email</a>
  File "c:\users\castle\documents\microblog\venv\lib\site-packages\flask\helpers.py", line 333, in url_for
    return appctx.app.handle_url_build_error(error, endpoint, values)
  File "c:\users\castle\documents\microblog\venv\lib\site-packages\flask\app.py", line 1805, in handle_url_build_error
    reraise(exc_type, exc_value, tb)
  File "c:\users\castle\documents\microblog\venv\lib\site-packages\flask\_compat.py", line 33, in reraise
    raise value
  File "c:\users\castle\documents\microblog\venv\lib\site-packages\flask\helpers.py", line 323, in url_for
    force_external=external)
  File "c:\users\castle\documents\microblog\venv\lib\site-packages\werkzeug\routing.py", line 1776, in build
    raise BuildError(endpoint, values, method, self)
werkzeug.routing.BuildError: Could not build url for endpoint 'emailpost'. Did you forget to specify values ['postid']?
2018-05-09 19:49:44,936 INFO: Microblog startup [in C:\Users\Castle\Documents\microblog\app\__init__.py:48]
2018-05-09 19:49:48,054 ERROR: Exception on /explore [GET] [in c:\users\castle\documents\microblog\venv\lib\site-packages\flask\app.py:1560]
Traceback (most recent call last):
  File "c:\users\castle\documents\microblog\venv\lib\site-packages\flask\app.py", line 1982, in wsgi_app
    response = self.full_dispatch_request()
  File "c:\users\castle\documents\microblog\venv\lib\site-packages\flask\app.py", line 1614, in full_dispatch_request
    rv = self.handle_user_exception(e)
  File "c:\users\castle\documents\microblog\venv\lib\site-packages\flask\app.py", line 1517, in handle_user_exception
    reraise(exc_type, exc_value, tb)
  File "c:\users\castle\documents\microblog\venv\lib\site-packages\flask\_compat.py", line 33, in reraise
    raise value
  File "c:\users\castle\documents\microblog\venv\lib\site-packages\flask\app.py", line 1612, in full_dispatch_request
    rv = self.dispatch_request()
  File "c:\users\castle\documents\microblog\venv\lib\site-packages\flask\app.py", line 1598, in dispatch_request
    return self.view_functions[rule.endpoint](**req.view_args)
  File "c:\users\castle\documents\microblog\venv\lib\site-packages\flask_login\utils.py", line 261, in decorated_view
    return func(*args, **kwargs)
  File "C:\Users\Castle\Documents\microblog\app\routes.py", line 157, in explore
    next_url=next_url, prev_url=prev_url)
  File "c:\users\castle\documents\microblog\venv\lib\site-packages\flask\templating.py", line 134, in render_template
    context, ctx.app)
  File "c:\users\castle\documents\microblog\venv\lib\site-packages\flask\templating.py", line 116, in _render
    rv = template.render(context)
  File "c:\users\castle\documents\microblog\venv\lib\site-packages\jinja2\asyncsupport.py", line 76, in render
    return original_render(self, *args, **kwargs)
  File "c:\users\castle\documents\microblog\venv\lib\site-packages\jinja2\environment.py", line 1008, in render
    return self.environment.handle_exception(exc_info, True)
  File "c:\users\castle\documents\microblog\venv\lib\site-packages\jinja2\environment.py", line 780, in handle_exception
    reraise(exc_type, exc_value, tb)
  File "c:\users\castle\documents\microblog\venv\lib\site-packages\jinja2\_compat.py", line 37, in reraise
    raise value.with_traceback(tb)
  File "C:\Users\Castle\Documents\microblog\app\templates\index.html", line 1, in top-level template code
    {% extends "base.html" %}
  File "C:\Users\Castle\Documents\microblog\app\templates\base.html", line 32, in top-level template code
    {% block content %}{% endblock %}
  File "C:\Users\Castle\Documents\microblog\app\templates\index.html", line 19, in block "content"
    {% include '_post.html' %}
  File "C:\Users\Castle\Documents\microblog\app\templates\_post.html", line 10, in top-level template code
    <br><a href="{{url_for('emailpost')}}/{{post.id}}">Send to Email</a>
  File "c:\users\castle\documents\microblog\venv\lib\site-packages\flask\helpers.py", line 333, in url_for
    return appctx.app.handle_url_build_error(error, endpoint, values)
  File "c:\users\castle\documents\microblog\venv\lib\site-packages\flask\app.py", line 1805, in handle_url_build_error
    reraise(exc_type, exc_value, tb)
  File "c:\users\castle\documents\microblog\venv\lib\site-packages\flask\_compat.py", line 33, in reraise
    raise value
  File "c:\users\castle\documents\microblog\venv\lib\site-packages\flask\helpers.py", line 323, in url_for
    force_external=external)
  File "c:\users\castle\documents\microblog\venv\lib\site-packages\werkzeug\routing.py", line 1776, in build
    raise BuildError(endpoint, values, method, self)
werkzeug.routing.BuildError: Could not build url for endpoint 'emailpost'. Did you forget to specify values ['postid']?
